#VRML_SIM R2020b utf8
WorldInfo {
  basicTimeStep 2
  coordinateSystem "NUE"
}
Viewpoint {
  orientation -0.26388260618570303 -0.952583148851911 -0.1514969130907276 1.1237326987149983
  position -9.392416215263529 4.306839251224441 5.794688597417306
}
TexturedBackground {
}
TexturedBackgroundLight {
}
RectangleArena {
  floorSize 6 9
  floorTileSize 1.5 1.5
  wallHeight 0.001
}
Robot {
  translation 0 0.8 0
  children [
    DEF body Shape {
      appearance PBRAppearance {
        baseColorMap ImageTexture {
          url [
            "textures/water.jpg"
          ]
        }
        metalness 0
      }
      geometry Cylinder {
        height 0.1
        radius 0.6
      }
      castShadows FALSE
    }
    Hinge2Joint {
      jointParameters HingeJointParameters {
      }
      jointParameters2 JointParameters {
      }
      device [
        RotationalMotor {
          name "X rotational motor A"
          maxTorque 1000
        }
        PositionSensor {
          name "X position sensor A"
        }
      ]
      device2 [
        RotationalMotor {
          name "Z rotational motor A"
          maxTorque 1000
        }
        PositionSensor {
          name "Z position sensor A"
        }
      ]
      endPoint Solid {
        translation -3.132605147929815e-13 0.00022956194274170732 -1.2420957273116862e-20
        children [
          DEF shaft Shape {
            appearance PBRAppearance {
              baseColor 0 0 1
              metalness 0
            }
            geometry Cylinder {
              height 0.3
              radius 0.05
            }
            castShadows FALSE
          }
          SliderJoint {
            jointParameters JointParameters {
              axis 0 1 0
              minStop -0.4
              dampingConstant 10
              staticFriction 0.2
            }
            device [
              LinearMotor {
                name "Spring linear motor A"
                maxForce 1600
              }
              PositionSensor {
                name "Spring position sensor A"
              }
            ]
            endPoint Solid {
              children [
                DEF leg Shape {
                  appearance PBRAppearance {
                    baseColor 1 1 0
                    metalness 0
                  }
                  geometry Cylinder {
                    height 1.58
                    radius 0.02
                  }
                  castShadows FALSE
                }
                Transform {
                  translation 0 -0.77 0
                  children [
                    DEF foot Shape {
                      appearance PBRAppearance {
                        baseColor 1 0 0
                        metalness 0
                      }
                      geometry Sphere {
                        radius 0.03
                        subdivision 3
                      }
                      castShadows FALSE
                    }
                    TouchSensor {
                      name "touch sensor A"
                      boundingObject USE foot
                      physics Physics {
                      }
                    }
                  ]
                }
              ]
              boundingObject USE leg
              physics Physics {
                density -1
                mass 1
              }
            }
          }
        ]
        boundingObject USE shaft
        physics Physics {
          density -1
          mass 0.5
        }
      }
    }
    InertialUnit {
      boundingObject USE body
      physics Physics {
        density -1
        mass 0.5
      }
    }
  ]
  boundingObject USE body
  physics Physics {
    density -1
    mass 15
  }
  controller "my_controller_2_leg"
}
Robot {
  translation 0 2.49 -0.86
  children [
    DEF externBody Shape {
      geometry Sphere {
        radius 0.1
      }
      castShadows FALSE
    }
    HingeJoint {
      jointParameters HingeJointParameters {
        position 0.2
      }
      endPoint Solid {
        translation 0 -1.4701000000000148 -0.29800400000000327
        rotation 1 0 0 0.1999999999999989
        children [
          DEF externBall Shape {
            appearance PBRAppearance {
              roughness 0.5
            }
            geometry Sphere {
              radius 0.2
              subdivision 3
            }
            castShadows FALSE
          }
          Transform {
            translation 0 0.75 0
            children [
              Shape {
                appearance PBRAppearance {
                  baseColor 1 0 0
                  roughness 0.5
                  metalness 0
                  IBLStrength 2
                }
                geometry Cylinder {
                  height 1.5
                  radius 0.01
                }
                castShadows FALSE
              }
            ]
          }
        ]
        boundingObject USE externBall
        physics Physics {
          density -1
          mass 2
        }
      }
    }
  ]
  name "robot(1)"
  boundingObject USE externBody
}
